2020-09-02 23:35:46 [INFO] config: Config(feed=FeedConfig(base_url='https://release-feeds.zhimingwang.org/', author='release-feeds', aggregate_title='Aggregate software releases'), packages=['ffmpeg', 'golang-defaults', 'pandoc', 'python3-defaults', 'rustc', 'zsh'])
2020-09-02 23:35:46 [INFO] GET https://sources.debian.org/api/src/ffmpeg/
2020-09-02 23:35:46 [INFO] GET https://sources.debian.org/api/src/pandoc/
2020-09-02 23:35:46 [INFO] GET https://sources.debian.org/api/src/python3-defaults/
2020-09-02 23:35:46 [INFO] GET https://sources.debian.org/api/src/rustc/
2020-09-02 23:35:46 [INFO] GET https://sources.debian.org/api/src/zsh/
2020-09-02 23:35:47 [INFO] GET https://sources.debian.org/api/src/ffmpeg/7:4.3.1-2/debian/watch
2020-09-02 23:35:47 [INFO] GET https://sources.debian.org/api/src/pandoc/2.9.2.1-1/debian/watch
2020-09-02 23:35:47 [INFO] GET https://sources.debian.org/api/src/python3-defaults/3.8.2-3/debian/watch
2020-09-02 23:35:47 [INFO] GET https://sources.debian.org/api/src/zsh/5.8-5/debian/watch
2020-09-02 23:35:47 [INFO] GET https://sources.debian.org/api/src/rustc/1.46.0+dfsg1-1/debian/watch
2020-09-02 23:35:47 [INFO] golang-defaults 1.15.1: https://golang.org/dl/go1.15.1.src.tar.gz
2020-09-02 23:35:47 [INFO] GET https://sources.debian.org/data/main/f/ffmpeg/7:4.3.1-2/debian/watch
2020-09-02 23:35:47 [INFO] GET https://sources.debian.org/data/main/p/python3-defaults/3.8.2-3/debian/watch
2020-09-02 23:35:47 [INFO] GET https://sources.debian.org/data/main/z/zsh/5.8-5/debian/watch
2020-09-02 23:35:47 [INFO] GET https://sources.debian.org/data/main/p/pandoc/2.9.2.1-1/debian/watch
2020-09-02 23:35:47 [INFO] GET https://sources.debian.org/data/main/r/rustc/1.46.0+dfsg1-1/debian/watch
2020-09-02 23:35:48 [INFO] python3-defaults 3.8.5: https://www.python.org/ftp/python/3.8.5/Python-3.8.5.tar.xz
2020-09-02 23:35:48 [ERROR] failed to update entry for zsh
Traceback (most recent call last):
  File "src/update.py", line 236, in uscan
    report = subprocess.check_output(
  File "/usr/lib/python3.8/subprocess.py", line 411, in check_output
    return run(*popenargs, stdout=PIPE, timeout=timeout, check=True,
  File "/usr/lib/python3.8/subprocess.py", line 512, in run
    raise CalledProcessError(retcode, process.args,
subprocess.CalledProcessError: Command '['uscan', '--safe', '--dehs']' returned non-zero exit status 1.

During handling of the above exception, another exception occurred:

Traceback (most recent call last):
  File "src/update.py", line 299, in try_updating_registry_entry
    entry = try_updating_entry(package, existing_entry=existing_entry)
  File "src/update.py", line 265, in try_updating_entry
    latest_version = get_package_version(package)
  File "src/update.py", line 257, in get_package_version
    version = uscan(package, source_dir)
  File "src/update.py", line 240, in uscan
    raise RuntimeError(f"uscan for {package} failed")
RuntimeError: uscan for zsh failed
2020-09-02 23:35:48 [INFO] rustc 1.46.0: https://static.rust-lang.org/dist/rustc-1.46.0-src.tar.xz
2020-09-02 23:35:48 [INFO] pandoc 2.10.1: https://hackage.haskell.org/package/pandoc-2.10.1/pandoc-2.10.1.tar.gz
2020-09-02 23:35:49 [INFO] ffmpeg 4.3.1: https://ffmpeg.org/releases/ffmpeg-4.3.1.tar.xz
2020-09-02 23:35:49 [INFO] no updates found
2020-09-02 23:35:49 [ERROR] failed: zsh
