2020-07-31 14:22:50 [INFO] config: Config(feed=FeedConfig(base_url='https://release-feeds.zhimingwang.org/', author='release-feeds', aggregate_title='Aggregate software releases'), packages=['ffmpeg', 'golang-defaults', 'pandoc', 'python3-defaults', 'rustc', 'zsh'])
2020-07-31 14:22:50 [INFO] GET https://sources.debian.org/api/src/python3-defaults/
2020-07-31 14:22:50 [INFO] GET https://sources.debian.org/api/src/pandoc/
2020-07-31 14:22:50 [INFO] GET https://sources.debian.org/api/src/rustc/
2020-07-31 14:22:50 [INFO] GET https://sources.debian.org/api/src/ffmpeg/
2020-07-31 14:22:50 [INFO] GET https://sources.debian.org/api/src/zsh/
2020-07-31 14:22:50 [ERROR] failed to update entry for python3-defaults
Traceback (most recent call last):
  File "src/update.py", line 285, in try_updating_registry_entry
    entry = try_updating_entry(package, existing_entry=existing_entry)
  File "src/update.py", line 251, in try_updating_entry
    latest_version = get_package_version(package)
  File "src/update.py", line 242, in get_package_version
    acquire_watch_file(package, debian_dir)
  File "src/update.py", line 217, in acquire_watch_file
    download_watch_file(package, destdir)
  File "src/update.py", line 189, in download_watch_file
    raise RuntimeError(f"no sid version found for {package}: {r.text}")
RuntimeError: no sid version found for python3-defaults: {"package":"python3-defaults","path":"python3-defaults","pathl":[["python3-defaults","/src/python3-defaults/"]],"suite":"","type":"package","versions":[{"area":"main","suites":[],"version":"3.8.2-3"},{"area":"main","suites":["buster"],"version":"3.7.3-1"},{"area":"main","suites":["stretch"],"version":"3.5.3-1"},{"area":"main","suites":["jessie","jessie-kfreebsd"],"version":"3.4.2-2"},{"area":"main","suites":["wheezy"],"version":"3.2.3-6"},{"area":"main","suites":["squeeze"],"version":"3.1.3-12+squeeze1"}]}

2020-07-31 14:22:50 [ERROR] failed to update entry for zsh
Traceback (most recent call last):
  File "src/update.py", line 285, in try_updating_registry_entry
    entry = try_updating_entry(package, existing_entry=existing_entry)
  File "src/update.py", line 251, in try_updating_entry
    latest_version = get_package_version(package)
  File "src/update.py", line 242, in get_package_version
    acquire_watch_file(package, debian_dir)
  File "src/update.py", line 217, in acquire_watch_file
    download_watch_file(package, destdir)
  File "src/update.py", line 189, in download_watch_file
    raise RuntimeError(f"no sid version found for {package}: {r.text}")
RuntimeError: no sid version found for zsh: {"package":"zsh","path":"zsh","pathl":[["zsh","/src/zsh/"]],"suite":"","type":"package","versions":[{"area":"main","suites":[],"version":"5.8-5"},{"area":"main","suites":["buster"],"version":"5.7.1-1"},{"area":"main","suites":["stretch"],"version":"5.3.1-4"},{"area":"main","suites":["jessie","jessie-kfreebsd"],"version":"5.0.7-5"},{"area":"main","suites":["wheezy"],"version":"4.3.17-1"},{"area":"main","suites":["squeeze"],"version":"4.3.10-14"},{"area":"main","suites":["lenny"],"version":"4.3.6-6"},{"area":"main","suites":["etch","etch-m68k"],"version":"4.3.2-25"},{"area":"main","suites":["sarge"],"version":"4.2.5-7"},{"area":"main","suites":["woody"],"version":"4.0.4-33"},{"area":"main","suites":["potato"],"version":"3.1.9.dev6-7"},{"area":"main","suites":["slink"],"version":"3.1.2-10"},{"area":"main","suites":["hamm"],"version":"3.1.2-8"}]}

2020-07-31 14:22:50 [ERROR] failed to update entry for pandoc
Traceback (most recent call last):
  File "src/update.py", line 285, in try_updating_registry_entry
    entry = try_updating_entry(package, existing_entry=existing_entry)
  File "src/update.py", line 251, in try_updating_entry
    latest_version = get_package_version(package)
  File "src/update.py", line 242, in get_package_version
    acquire_watch_file(package, debian_dir)
  File "src/update.py", line 217, in acquire_watch_file
    download_watch_file(package, destdir)
  File "src/update.py", line 189, in download_watch_file
    raise RuntimeError(f"no sid version found for {package}: {r.text}")
RuntimeError: no sid version found for pandoc: {"package":"pandoc","path":"pandoc","pathl":[["pandoc","/src/pandoc/"]],"suite":"","type":"package","versions":[{"area":"main","suites":[],"version":"2.9.1.1-3"},{"area":"main","suites":[],"version":"2.9.1.1-2"},{"area":"main","suites":[],"version":"2.5-3"},{"area":"main","suites":["buster"],"version":"2.2.1-3"},{"area":"main","suites":["stretch"],"version":"1.17.2~dfsg-3"},{"area":"main","suites":["jessie","jessie-kfreebsd"],"version":"1.12.4.2~dfsg-1"},{"area":"main","suites":["wheezy"],"version":"1.9.4.2-2"},{"area":"main","suites":["squeeze"],"version":"1.5.1.1-5"},{"area":"main","suites":["lenny"],"version":"0.46+2"}]}

2020-07-31 14:22:50 [ERROR] failed to update entry for ffmpeg
Traceback (most recent call last):
  File "src/update.py", line 285, in try_updating_registry_entry
    entry = try_updating_entry(package, existing_entry=existing_entry)
  File "src/update.py", line 251, in try_updating_entry
    latest_version = get_package_version(package)
  File "src/update.py", line 242, in get_package_version
    acquire_watch_file(package, debian_dir)
  File "src/update.py", line 217, in acquire_watch_file
    download_watch_file(package, destdir)
  File "src/update.py", line 189, in download_watch_file
    raise RuntimeError(f"no sid version found for {package}: {r.text}")
RuntimeError: no sid version found for ffmpeg: {"package":"ffmpeg","path":"ffmpeg","pathl":[["ffmpeg","/src/ffmpeg/"]],"suite":"","type":"package","versions":[{"area":"main","suites":[],"version":"7:4.3-3"},{"area":"main","suites":[],"version":"7:4.1.6-1~deb10u1"},{"area":"main","suites":["buster"],"version":"7:4.1.4-1~deb10u1"},{"area":"main","suites":["stretch"],"version":"7:3.2.14-1~deb9u1"},{"area":"main","suites":["jessie-backports"],"version":"7:3.2.10-1~deb9u1~bpo8+1"},{"area":"main","suites":["jessie-backports"],"version":"7:3.2.5-1~bpo8+1"},{"area":"main","suites":["squeeze-lts"],"version":"4:0.5.10-1+deb6u1"},{"area":"main","suites":["squeeze"],"version":"4:0.5.10-1"},{"area":"main","suites":["etch"],"version":"0.cvs20060823-8+etch1"},{"area":"main","suites":["etch-m68k"],"version":"0.cvs20060823-8"},{"area":"main","suites":["sarge"],"version":"0.cvs20050313-2sarge1"}]}

2020-07-31 14:22:50 [ERROR] failed to update entry for rustc
Traceback (most recent call last):
  File "src/update.py", line 285, in try_updating_registry_entry
    entry = try_updating_entry(package, existing_entry=existing_entry)
  File "src/update.py", line 251, in try_updating_entry
    latest_version = get_package_version(package)
  File "src/update.py", line 242, in get_package_version
    acquire_watch_file(package, debian_dir)
  File "src/update.py", line 217, in acquire_watch_file
    download_watch_file(package, destdir)
  File "src/update.py", line 189, in download_watch_file
    raise RuntimeError(f"no sid version found for {package}: {r.text}")
RuntimeError: no sid version found for rustc: {"package":"rustc","path":"rustc","pathl":[["rustc","/src/rustc/"]],"suite":"","type":"package","versions":[{"area":"main","suites":[],"version":"1.44.1+dfsg1-3"},{"area":"main","suites":[],"version":"1.44.1+dfsg1-2"},{"area":"main","suites":[],"version":"1.44.1+dfsg1-1"},{"area":"main","suites":[],"version":"1.43.0+dfsg1-1"},{"area":"main","suites":[],"version":"1.42.0+dfsg1-1"},{"area":"main","suites":[],"version":"1.41.1+dfsg1-1"},{"area":"main","suites":[],"version":"1.40.0+dfsg1-5"},{"area":"main","suites":[],"version":"1.40.0+dfsg1-1"},{"area":"main","suites":[],"version":"1.39.0+dfsg1-4"},{"area":"main","suites":[],"version":"1.38.0+dfsg1-2"},{"area":"main","suites":[],"version":"1.37.0+dfsg1-1"},{"area":"main","suites":[],"version":"1.36.0+dfsg1-2"},{"area":"main","suites":["buster"],"version":"1.34.2+dfsg1-1"},{"area":"main","suites":["stretch"],"version":"1.34.2+dfsg1-1~deb9u1"}]}

2020-07-31 14:22:52 [INFO] golang-defaults 1.14.6: https://golang.org/dl/go1.14.6.src.tar.gz
2020-07-31 14:22:52 [INFO] no updates found
2020-07-31 14:22:52 [ERROR] failed: python3-defaults, zsh, pandoc, ffmpeg, rustc
