2021-05-02 22:47:45 [INFO] persisted: Persisted(last_successful_crawls={'ffmpeg': '2021-05-02 22:32:43.470237+00:00', 'golang-defaults': '2021-05-02 22:32:41.605764+00:00', 'python3-defaults': '2021-05-02 22:32:42.373000+00:00', 'rustc': '2021-05-02 22:32:42.584558+00:00', 'zsh': '2021-05-02 22:32:42.740073+00:00'})
2021-05-02 22:47:45 [INFO] config: Config(feed=FeedConfig(base_url='https://release-feeds.zhimingwang.org/', author='release-feeds', aggregate_title='Aggregate software releases'), packages=['ffmpeg', 'golang-defaults', 'python3-defaults', 'rustc', 'zsh'])
2021-05-02 22:47:45 [INFO] GET https://sources.debian.org/api/src/ffmpeg/
2021-05-02 22:47:46 [INFO] GET https://sources.debian.org/api/src/python3-defaults/
2021-05-02 22:47:46 [INFO] GET https://sources.debian.org/api/src/rustc/
2021-05-02 22:47:46 [INFO] GET https://sources.debian.org/api/src/zsh/
2021-05-02 22:47:46 [INFO] GET https://sources.debian.org/api/src/zsh/5.8-6/debian/watch
2021-05-02 22:47:46 [INFO] GET https://sources.debian.org/api/src/ffmpeg/7:4.3.2-0+deb11u1/debian/watch
2021-05-02 22:47:46 [INFO] GET https://sources.debian.org/api/src/rustc/1.48.0+dfsg1-2/debian/watch
2021-05-02 22:47:46 [INFO] GET https://sources.debian.org/data/main/z/zsh/5.8-6/debian/watch
2021-05-02 22:47:46 [INFO] GET https://sources.debian.org/data/main/f/ffmpeg/7:4.3.2-0+deb11u1/debian/watch
2021-05-02 22:47:46 [INFO] GET https://sources.debian.org/data/main/r/rustc/1.48.0+dfsg1-2/debian/watch
2021-05-02 22:47:47 [INFO] zsh 5.8: https://www.zsh.org/pub/zsh-5.8.tar.xz
2021-05-02 22:47:48 [INFO] rustc 1.51.0: https://static.rust-lang.org/dist/rustc-1.51.0-src.tar.xz
2021-05-02 22:47:48 [INFO] ffmpeg 4.4: https://ffmpeg.org/releases/ffmpeg-4.4.tar.xz
2021-05-02 22:47:50 [INFO] golang-defaults 1.16.3: https://golang.org/dl/go1.16.3.src.tar.gz
2021-05-02 22:47:51 [ERROR] failed to update entry for python3-defaults
Traceback (most recent call last):
  File "/usr/lib/python3/dist-packages/urllib3/connection.py", line 159, in _new_conn
    conn = connection.create_connection(
  File "/usr/lib/python3/dist-packages/urllib3/util/connection.py", line 84, in create_connection
    raise err
  File "/usr/lib/python3/dist-packages/urllib3/util/connection.py", line 74, in create_connection
    sock.connect(sa)
OSError: [Errno 101] Network is unreachable

During handling of the above exception, another exception occurred:

Traceback (most recent call last):
  File "/usr/lib/python3/dist-packages/urllib3/connectionpool.py", line 665, in urlopen
    httplib_response = self._make_request(
  File "/usr/lib/python3/dist-packages/urllib3/connectionpool.py", line 376, in _make_request
    self._validate_conn(conn)
  File "/usr/lib/python3/dist-packages/urllib3/connectionpool.py", line 996, in _validate_conn
    conn.connect()
  File "/usr/lib/python3/dist-packages/urllib3/connection.py", line 314, in connect
    conn = self._new_conn()
  File "/usr/lib/python3/dist-packages/urllib3/connection.py", line 171, in _new_conn
    raise NewConnectionError(
urllib3.exceptions.NewConnectionError: <urllib3.connection.VerifiedHTTPSConnection object at 0x7f36d520ec10>: Failed to establish a new connection: [Errno 101] Network is unreachable

During handling of the above exception, another exception occurred:

Traceback (most recent call last):
  File "/usr/lib/python3/dist-packages/requests/adapters.py", line 439, in send
    resp = conn.urlopen(
  File "/usr/lib/python3/dist-packages/urllib3/connectionpool.py", line 719, in urlopen
    retries = retries.increment(
  File "/usr/lib/python3/dist-packages/urllib3/util/retry.py", line 436, in increment
    raise MaxRetryError(_pool, url, error or ResponseError(cause))
urllib3.exceptions.MaxRetryError: HTTPSConnectionPool(host='sources.debian.org', port=443): Max retries exceeded with url: /api/src/python3-defaults/ (Caused by NewConnectionError('<urllib3.connection.VerifiedHTTPSConnection object at 0x7f36d520ec10>: Failed to establish a new connection: [Errno 101] Network is unreachable'))

During handling of the above exception, another exception occurred:

Traceback (most recent call last):
  File "src/update.py", line 354, in try_updating_registry_entry
    entry = try_updating_entry(package, existing_entry=existing_entry)
  File "src/update.py", line 319, in try_updating_entry
    latest_version = get_package_version(package)
  File "src/update.py", line 310, in get_package_version
    acquire_watch_file(package, debian_dir)
  File "src/update.py", line 276, in acquire_watch_file
    download_watch_file(package, destdir)
  File "/home/runner/.local/lib/python3.8/site-packages/tenacity/__init__.py", line 339, in wrapped_f
    return self(f, *args, **kw)
  File "/home/runner/.local/lib/python3.8/site-packages/tenacity/__init__.py", line 430, in __call__
    do = self.iter(retry_state=retry_state)
  File "/home/runner/.local/lib/python3.8/site-packages/tenacity/__init__.py", line 367, in iter
    return fut.result()
  File "/usr/lib/python3.8/concurrent/futures/_base.py", line 432, in result
    return self.__get_result()
  File "/usr/lib/python3.8/concurrent/futures/_base.py", line 388, in __get_result
    raise self._exception
  File "/home/runner/.local/lib/python3.8/site-packages/tenacity/__init__.py", line 433, in __call__
    result = fn(*args, **kwargs)
  File "src/update.py", line 238, in download_watch_file
    r = session.get(url)
  File "/usr/lib/python3/dist-packages/requests/sessions.py", line 546, in get
    return self.request('GET', url, **kwargs)
  File "/usr/lib/python3/dist-packages/requests/sessions.py", line 533, in request
    resp = self.send(prep, **send_kwargs)
  File "/usr/lib/python3/dist-packages/requests/sessions.py", line 646, in send
    r = adapter.send(request, **kwargs)
  File "/usr/lib/python3/dist-packages/requests/adapters.py", line 516, in send
    raise ConnectionError(e, request=request)
requests.exceptions.ConnectionError: HTTPSConnectionPool(host='sources.debian.org', port=443): Max retries exceeded with url: /api/src/python3-defaults/ (Caused by NewConnectionError('<urllib3.connection.VerifiedHTTPSConnection object at 0x7f36d520ec10>: Failed to establish a new connection: [Errno 101] Network is unreachable'))
2021-05-02 22:47:51 [INFO] no updates found
2021-05-02 22:47:51 [ERROR] failed: python3-defaults
