2022-05-23 08:46:47 [INFO] persisted: Persisted(last_successful_crawls={'ffmpeg': '2022-05-23 08:32:04.434915+00:00', 'golang-defaults': '2022-05-23 08:32:03.582134+00:00', 'python3-defaults': '2022-05-23 08:32:03.097777+00:00', 'rustc': '2022-05-23 08:32:03.511303+00:00', 'zsh': '2022-05-23 08:32:03.650595+00:00'})
2022-05-23 08:46:47 [INFO] config: Config(feed=FeedConfig(base_url='https://release-feeds.zhimingwang.org/', author='release-feeds', aggregate_title='Aggregate software releases'), packages=['ffmpeg', 'golang-defaults', 'python3-defaults', 'rustc', 'zsh'])
2022-05-23 08:46:47 [INFO] GET https://sources.debian.org/api/src/ffmpeg/
2022-05-23 08:46:47 [INFO] GET https://sources.debian.org/api/src/rustc/
2022-05-23 08:46:47 [INFO] GET https://sources.debian.org/api/src/python3-defaults/
2022-05-23 08:46:47 [INFO] GET https://sources.debian.org/api/src/zsh/
2022-05-23 08:46:47 [WARNING] retrying download_watch_file for python3-defaults (attempt #1)
2022-05-23 08:46:47 [WARNING] retrying download_watch_file for rustc (attempt #1)
2022-05-23 08:46:47 [WARNING] retrying download_watch_file for ffmpeg (attempt #1)
2022-05-23 08:46:47 [WARNING] retrying download_watch_file for zsh (attempt #1)
2022-05-23 08:46:48 [INFO] golang-defaults 1.18.2: https://golang.org/dl/go1.18.2.src.tar.gz
2022-05-23 08:46:49 [INFO] GET https://sources.debian.org/api/src/python3-defaults/
2022-05-23 08:46:49 [INFO] GET https://sources.debian.org/api/src/rustc/
2022-05-23 08:46:49 [INFO] GET https://sources.debian.org/api/src/ffmpeg/
2022-05-23 08:46:49 [INFO] GET https://sources.debian.org/api/src/zsh/
2022-05-23 08:46:49 [WARNING] retrying download_watch_file for python3-defaults (attempt #2)
2022-05-23 08:46:49 [WARNING] retrying download_watch_file for rustc (attempt #2)
2022-05-23 08:46:49 [WARNING] retrying download_watch_file for ffmpeg (attempt #2)
2022-05-23 08:46:49 [WARNING] retrying download_watch_file for zsh (attempt #2)
2022-05-23 08:46:53 [INFO] GET https://sources.debian.org/api/src/python3-defaults/
2022-05-23 08:46:53 [INFO] GET https://sources.debian.org/api/src/rustc/
2022-05-23 08:46:53 [INFO] GET https://sources.debian.org/api/src/ffmpeg/
2022-05-23 08:46:53 [INFO] GET https://sources.debian.org/api/src/zsh/
2022-05-23 08:46:53 [WARNING] retrying download_watch_file for python3-defaults (attempt #3)
2022-05-23 08:46:53 [WARNING] failed to update entry for python3-defaults (0:14:51 since last successful crawl): no sid version found for python3-defaults: {"package":"python3-defaults","path":"python3-defaults","pathl":[["python3-defaults","/src/python3-defaults/"]],"suite":"","type":"package","versions":[{"area":"main","suites":[],"version":"3.10.4-1"},{"area":"main","suites":["bullseye"],"version":"3.9.2-3"},{"area":"main","suites":["buster"],"version":"3.7.3-1"},{"area":"main","suites":["stretch"],"version":"3.5.3-1"},{"area":"main","suites":["jessie","jessie-kfreebsd"],"version":"3.4.2-2"},{"area":"main","suites":["wheezy"],"version":"3.2.3-6"},{"area":"main","suites":["squeeze"],"version":"3.1.3-12+squeeze1"}]}

2022-05-23 08:46:53 [WARNING] retrying download_watch_file for rustc (attempt #3)
2022-05-23 08:46:53 [WARNING] failed to update entry for rustc (0:14:50 since last successful crawl): no sid version found for rustc: {"package":"rustc","path":"rustc","pathl":[["rustc","/src/rustc/"]],"suite":"","type":"package","versions":[{"area":"main","suites":[],"version":"1.59.0+dfsg1-1"},{"area":"main","suites":[],"version":"1.58.1+dfsg1-1"},{"area":"main","suites":[],"version":"1.57.0+dfsg1-1"},{"area":"main","suites":[],"version":"1.56.0+dfsg1-2"},{"area":"main","suites":[],"version":"1.55.0+dfsg1-2"},{"area":"main","suites":[],"version":"1.54.0+dfsg1-3"},{"area":"main","suites":[],"version":"1.54.0+dfsg1-1"},{"area":"main","suites":["bullseye"],"version":"1.48.0+dfsg1-2"},{"area":"main","suites":[],"version":"1.47.0+dfsg1-1"},{"area":"main","suites":["buster"],"version":"1.41.1+dfsg1-1~deb10u1"},{"area":"main","suites":[],"version":"1.36.0+dfsg1-2"},{"area":"main","suites":["buster"],"version":"1.34.2+dfsg1-1"},{"area":"main","suites":["stretch"],"version":"1.34.2+dfsg1-1~deb9u1"}]}

2022-05-23 08:46:53 [WARNING] retrying download_watch_file for zsh (attempt #3)
2022-05-23 08:46:53 [WARNING] failed to update entry for zsh (0:14:50 since last successful crawl): no sid version found for zsh: {"package":"zsh","path":"zsh","pathl":[["zsh","/src/zsh/"]],"suite":"","type":"package","versions":[{"area":"main","suites":[],"version":"5.9-1"},{"area":"main","suites":[],"version":"5.8.1-1"},{"area":"main","suites":["bullseye"],"version":"5.8-6+deb11u1"},{"area":"main","suites":["buster"],"version":"5.7.1-1+deb10u1"},{"area":"main","suites":["stretch"],"version":"5.3.1-4"},{"area":"main","suites":["jessie","jessie-kfreebsd"],"version":"5.0.7-5"},{"area":"main","suites":["wheezy"],"version":"4.3.17-1"},{"area":"main","suites":["squeeze"],"version":"4.3.10-14"},{"area":"main","suites":["lenny"],"version":"4.3.6-6"},{"area":"main","suites":["etch","etch-m68k"],"version":"4.3.2-25"},{"area":"main","suites":["sarge"],"version":"4.2.5-7"},{"area":"main","suites":["woody"],"version":"4.0.4-33"},{"area":"main","suites":["potato"],"version":"3.1.9.dev6-7"},{"area":"main","suites":["slink"],"version":"3.1.2-10"},{"area":"main","suites":["hamm"],"version":"3.1.2-8"}]}

2022-05-23 08:46:54 [ERROR] failed to update entry for ffmpeg
Traceback (most recent call last):
  File "/usr/lib/python3/dist-packages/urllib3/connectionpool.py", line 665, in urlopen
    httplib_response = self._make_request(
  File "/usr/lib/python3/dist-packages/urllib3/connectionpool.py", line 421, in _make_request
    six.raise_from(e, None)
  File "<string>", line 3, in raise_from
  File "/usr/lib/python3/dist-packages/urllib3/connectionpool.py", line 416, in _make_request
    httplib_response = conn.getresponse()
  File "/usr/lib/python3.8/http/client.py", line 1348, in getresponse
    response.begin()
  File "/usr/lib/python3.8/http/client.py", line 316, in begin
    version, status, reason = self._read_status()
  File "/usr/lib/python3.8/http/client.py", line 285, in _read_status
    raise RemoteDisconnected("Remote end closed connection without"
http.client.RemoteDisconnected: Remote end closed connection without response

During handling of the above exception, another exception occurred:

Traceback (most recent call last):
  File "/usr/lib/python3/dist-packages/requests/adapters.py", line 439, in send
    resp = conn.urlopen(
  File "/usr/lib/python3/dist-packages/urllib3/connectionpool.py", line 719, in urlopen
    retries = retries.increment(
  File "/usr/lib/python3/dist-packages/urllib3/util/retry.py", line 400, in increment
    raise six.reraise(type(error), error, _stacktrace)
  File "/usr/lib/python3/dist-packages/six.py", line 702, in reraise
    raise value.with_traceback(tb)
  File "/usr/lib/python3/dist-packages/urllib3/connectionpool.py", line 665, in urlopen
    httplib_response = self._make_request(
  File "/usr/lib/python3/dist-packages/urllib3/connectionpool.py", line 421, in _make_request
    six.raise_from(e, None)
  File "<string>", line 3, in raise_from
  File "/usr/lib/python3/dist-packages/urllib3/connectionpool.py", line 416, in _make_request
    httplib_response = conn.getresponse()
  File "/usr/lib/python3.8/http/client.py", line 1348, in getresponse
    response.begin()
  File "/usr/lib/python3.8/http/client.py", line 316, in begin
    version, status, reason = self._read_status()
  File "/usr/lib/python3.8/http/client.py", line 285, in _read_status
    raise RemoteDisconnected("Remote end closed connection without"
urllib3.exceptions.ProtocolError: ('Connection aborted.', RemoteDisconnected('Remote end closed connection without response'))

During handling of the above exception, another exception occurred:

Traceback (most recent call last):
  File "src/update.py", line 354, in try_updating_registry_entry
    entry = try_updating_entry(package, existing_entry=existing_entry)
  File "src/update.py", line 319, in try_updating_entry
    latest_version = get_package_version(package)
  File "src/update.py", line 310, in get_package_version
    acquire_watch_file(package, debian_dir)
  File "src/update.py", line 276, in acquire_watch_file
    download_watch_file(package, destdir)
  File "/home/runner/.local/lib/python3.8/site-packages/tenacity/__init__.py", line 324, in wrapped_f
    return self(f, *args, **kw)
  File "/home/runner/.local/lib/python3.8/site-packages/tenacity/__init__.py", line 404, in __call__
    do = self.iter(retry_state=retry_state)
  File "/home/runner/.local/lib/python3.8/site-packages/tenacity/__init__.py", line 349, in iter
    return fut.result()
  File "/usr/lib/python3.8/concurrent/futures/_base.py", line 437, in result
    return self.__get_result()
  File "/usr/lib/python3.8/concurrent/futures/_base.py", line 389, in __get_result
    raise self._exception
  File "/home/runner/.local/lib/python3.8/site-packages/tenacity/__init__.py", line 407, in __call__
    result = fn(*args, **kwargs)
  File "src/update.py", line 238, in download_watch_file
    r = session.get(url)
  File "/usr/lib/python3/dist-packages/requests/sessions.py", line 546, in get
    return self.request('GET', url, **kwargs)
  File "/usr/lib/python3/dist-packages/requests/sessions.py", line 533, in request
    resp = self.send(prep, **send_kwargs)
  File "/usr/lib/python3/dist-packages/requests/sessions.py", line 646, in send
    r = adapter.send(request, **kwargs)
  File "/usr/lib/python3/dist-packages/requests/adapters.py", line 498, in send
    raise ConnectionError(err, request=request)
requests.exceptions.ConnectionError: ('Connection aborted.', RemoteDisconnected('Remote end closed connection without response'))
2022-05-23 08:46:54 [INFO] no updates found
2022-05-23 08:46:54 [ERROR] failed: ffmpeg
