2023-06-07 18:16:47 [INFO] persisted: Persisted(last_successful_crawls={'ffmpeg': '2023-06-07 18:04:23.026766+00:00', 'golang-defaults': '2023-06-07 18:04:22.186822+00:00', 'python3-defaults': '2023-06-07 18:04:21.520333+00:00', 'rustc': '2023-06-07 18:04:21.800528+00:00', 'zsh': '2023-06-07 18:04:22.158433+00:00'})
2023-06-07 18:16:47 [INFO] config: Config(feed=FeedConfig(base_url='https://release-feeds.zhimingwang.org/', author='release-feeds', aggregate_title='Aggregate software releases'), packages=['ffmpeg', 'golang-defaults', 'python3-defaults', 'rustc', 'zsh'])
2023-06-07 18:16:47 [INFO] GET https://sources.debian.org/api/src/ffmpeg/
2023-06-07 18:16:47 [INFO] GET https://sources.debian.org/api/src/python3-defaults/
2023-06-07 18:16:48 [INFO] GET https://sources.debian.org/api/src/rustc/
2023-06-07 18:16:48 [INFO] GET https://sources.debian.org/api/src/zsh/
2023-06-07 18:16:48 [ERROR] failed to update entry for rustc
Traceback (most recent call last):
  File "/usr/lib/python3/dist-packages/urllib3/connection.py", line 159, in _new_conn
    conn = connection.create_connection(
  File "/usr/lib/python3/dist-packages/urllib3/util/connection.py", line 84, in create_connection
    raise err
  File "/usr/lib/python3/dist-packages/urllib3/util/connection.py", line 74, in create_connection
    sock.connect(sa)
OSError: [Errno 101] Network is unreachable

During handling of the above exception, another exception occurred:

Traceback (most recent call last):
  File "/usr/lib/python3/dist-packages/urllib3/connectionpool.py", line 665, in urlopen
    httplib_response = self._make_request(
  File "/usr/lib/python3/dist-packages/urllib3/connectionpool.py", line 376, in _make_request
    self._validate_conn(conn)
  File "/usr/lib/python3/dist-packages/urllib3/connectionpool.py", line 996, in _validate_conn
    conn.connect()
  File "/usr/lib/python3/dist-packages/urllib3/connection.py", line 314, in connect
    conn = self._new_conn()
  File "/usr/lib/python3/dist-packages/urllib3/connection.py", line 171, in _new_conn
    raise NewConnectionError(
urllib3.exceptions.NewConnectionError: <urllib3.connection.VerifiedHTTPSConnection object at 0x7fecc457c490>: Failed to establish a new connection: [Errno 101] Network is unreachable

During handling of the above exception, another exception occurred:

Traceback (most recent call last):
  File "/usr/lib/python3/dist-packages/requests/adapters.py", line 439, in send
    resp = conn.urlopen(
  File "/usr/lib/python3/dist-packages/urllib3/connectionpool.py", line 719, in urlopen
    retries = retries.increment(
  File "/usr/lib/python3/dist-packages/urllib3/util/retry.py", line 436, in increment
    raise MaxRetryError(_pool, url, error or ResponseError(cause))
urllib3.exceptions.MaxRetryError: HTTPSConnectionPool(host='sources.debian.org', port=443): Max retries exceeded with url: /api/src/rustc/ (Caused by NewConnectionError('<urllib3.connection.VerifiedHTTPSConnection object at 0x7fecc457c490>: Failed to establish a new connection: [Errno 101] Network is unreachable'))

During handling of the above exception, another exception occurred:

Traceback (most recent call last):
  File "src/update.py", line 354, in try_updating_registry_entry
    entry = try_updating_entry(package, existing_entry=existing_entry)
  File "src/update.py", line 319, in try_updating_entry
    latest_version = get_package_version(package)
  File "src/update.py", line 310, in get_package_version
    acquire_watch_file(package, debian_dir)
  File "src/update.py", line 276, in acquire_watch_file
    download_watch_file(package, destdir)
  File "/home/runner/.local/lib/python3.8/site-packages/tenacity/__init__.py", line 289, in wrapped_f
    return self(f, *args, **kw)
  File "/home/runner/.local/lib/python3.8/site-packages/tenacity/__init__.py", line 379, in __call__
    do = self.iter(retry_state=retry_state)
  File "/home/runner/.local/lib/python3.8/site-packages/tenacity/__init__.py", line 314, in iter
    return fut.result()
  File "/usr/lib/python3.8/concurrent/futures/_base.py", line 437, in result
    return self.__get_result()
  File "/usr/lib/python3.8/concurrent/futures/_base.py", line 389, in __get_result
    raise self._exception
  File "/home/runner/.local/lib/python3.8/site-packages/tenacity/__init__.py", line 382, in __call__
    result = fn(*args, **kwargs)
  File "src/update.py", line 238, in download_watch_file
    r = session.get(url)
  File "/usr/lib/python3/dist-packages/requests/sessions.py", line 546, in get
    return self.request('GET', url, **kwargs)
  File "/usr/lib/python3/dist-packages/requests/sessions.py", line 533, in request
    resp = self.send(prep, **send_kwargs)
  File "/usr/lib/python3/dist-packages/requests/sessions.py", line 646, in send
    r = adapter.send(request, **kwargs)
  File "/usr/lib/python3/dist-packages/requests/adapters.py", line 516, in send
    raise ConnectionError(e, request=request)
requests.exceptions.ConnectionError: HTTPSConnectionPool(host='sources.debian.org', port=443): Max retries exceeded with url: /api/src/rustc/ (Caused by NewConnectionError('<urllib3.connection.VerifiedHTTPSConnection object at 0x7fecc457c490>: Failed to establish a new connection: [Errno 101] Network is unreachable'))
2023-06-07 18:16:48 [INFO] GET https://sources.debian.org/api/src/python3-defaults/3.11.2-1/debian/watch
2023-06-07 18:16:48 [INFO] GET https://sources.debian.org/api/src/ffmpeg/7:5.1.3-1/debian/watch
2023-06-07 18:16:48 [INFO] GET https://sources.debian.org/api/src/zsh/5.9-4/debian/watch
2023-06-07 18:16:48 [INFO] GET https://sources.debian.org/data/main/p/python3-defaults/3.11.2-1/debian/watch
2023-06-07 18:16:48 [INFO] GET https://sources.debian.org/data/main/f/ffmpeg/7%3A5.1.3-1/debian/watch
2023-06-07 18:16:48 [INFO] GET https://sources.debian.org/data/main/z/zsh/5.9-4/debian/watch
2023-06-07 18:16:49 [INFO] python3-defaults 3.11.4: https://www.python.org/ftp/python/3.11.4/Python-3.11.4.tar.xz
2023-06-07 18:16:49 [INFO] zsh 5.9: https://www.zsh.org/pub/zsh-5.9.tar.xz
2023-06-07 18:16:50 [INFO] golang-defaults 1.20.5: https://golang.org/dl/go1.20.5.src.tar.gz
2023-06-07 18:16:50 [INFO] ffmpeg 6.0: https://ffmpeg.org/releases/ffmpeg-6.0.tar.xz
2023-06-07 18:16:50 [INFO] no updates found
2023-06-07 18:16:50 [ERROR] failed: rustc
