2023-11-18 06:42:37 [INFO] persisted: Persisted(last_successful_crawls={'ffmpeg': '2023-11-18 06:33:49.139852+00:00', 'golang-defaults': '2023-11-18 06:33:47.939162+00:00', 'python3-defaults': '2023-11-18 06:33:47.428896+00:00', 'rustc': '2023-11-18 06:33:47.593403+00:00', 'zsh': '2023-11-18 06:33:48.218539+00:00'})
2023-11-18 06:42:37 [INFO] config: Config(feed=FeedConfig(base_url='https://release-feeds.zhimingwang.org/', author='release-feeds', aggregate_title='Aggregate software releases'), packages=['ffmpeg', 'golang-defaults', 'python3-defaults', 'rustc', 'zsh'])
2023-11-18 06:42:37 [INFO] GET https://sources.debian.org/api/src/zsh/
2023-11-18 06:42:37 [INFO] GET https://sources.debian.org/api/src/ffmpeg/
2023-11-18 06:42:37 [INFO] GET https://sources.debian.org/api/src/python3-defaults/
2023-11-18 06:42:37 [INFO] GET https://sources.debian.org/api/src/rustc/
2023-11-18 06:42:38 [INFO] golang-defaults 1.21.4: https://golang.org/dl/go1.21.4.src.tar.gz
2023-11-18 06:42:38 [INFO] GET https://sources.debian.org/api/src/python3-defaults/3.11.4-5/debian/watch
2023-11-18 06:42:38 [INFO] GET https://sources.debian.org/api/src/rustc/1.70.0+dfsg1-1/debian/watch
2023-11-18 06:42:38 [INFO] GET https://sources.debian.org/api/src/ffmpeg/7:6.1-2/debian/watch
2023-11-18 06:42:38 [ERROR] failed to update entry for ffmpeg
Traceback (most recent call last):
  File "/usr/lib/python3/dist-packages/urllib3/connectionpool.py", line 665, in urlopen
    httplib_response = self._make_request(
  File "/usr/lib/python3/dist-packages/urllib3/connectionpool.py", line 421, in _make_request
    six.raise_from(e, None)
  File "<string>", line 3, in raise_from
  File "/usr/lib/python3/dist-packages/urllib3/connectionpool.py", line 416, in _make_request
    httplib_response = conn.getresponse()
  File "/usr/lib/python3.8/http/client.py", line 1348, in getresponse
    response.begin()
  File "/usr/lib/python3.8/http/client.py", line 316, in begin
    version, status, reason = self._read_status()
  File "/usr/lib/python3.8/http/client.py", line 285, in _read_status
    raise RemoteDisconnected("Remote end closed connection without"
http.client.RemoteDisconnected: Remote end closed connection without response

During handling of the above exception, another exception occurred:

Traceback (most recent call last):
  File "/usr/lib/python3/dist-packages/requests/adapters.py", line 439, in send
    resp = conn.urlopen(
  File "/usr/lib/python3/dist-packages/urllib3/connectionpool.py", line 719, in urlopen
    retries = retries.increment(
  File "/usr/lib/python3/dist-packages/urllib3/util/retry.py", line 400, in increment
    raise six.reraise(type(error), error, _stacktrace)
  File "/usr/lib/python3/dist-packages/six.py", line 702, in reraise
    raise value.with_traceback(tb)
  File "/usr/lib/python3/dist-packages/urllib3/connectionpool.py", line 665, in urlopen
    httplib_response = self._make_request(
  File "/usr/lib/python3/dist-packages/urllib3/connectionpool.py", line 421, in _make_request
    six.raise_from(e, None)
  File "<string>", line 3, in raise_from
  File "/usr/lib/python3/dist-packages/urllib3/connectionpool.py", line 416, in _make_request
    httplib_response = conn.getresponse()
  File "/usr/lib/python3.8/http/client.py", line 1348, in getresponse
    response.begin()
  File "/usr/lib/python3.8/http/client.py", line 316, in begin
    version, status, reason = self._read_status()
  File "/usr/lib/python3.8/http/client.py", line 285, in _read_status
    raise RemoteDisconnected("Remote end closed connection without"
urllib3.exceptions.ProtocolError: ('Connection aborted.', RemoteDisconnected('Remote end closed connection without response'))

During handling of the above exception, another exception occurred:

Traceback (most recent call last):
  File "src/update.py", line 354, in try_updating_registry_entry
    entry = try_updating_entry(package, existing_entry=existing_entry)
  File "src/update.py", line 319, in try_updating_entry
    latest_version = get_package_version(package)
  File "src/update.py", line 310, in get_package_version
    acquire_watch_file(package, debian_dir)
  File "src/update.py", line 276, in acquire_watch_file
    download_watch_file(package, destdir)
  File "/home/runner/.local/lib/python3.8/site-packages/tenacity/__init__.py", line 289, in wrapped_f
    return self(f, *args, **kw)
  File "/home/runner/.local/lib/python3.8/site-packages/tenacity/__init__.py", line 379, in __call__
    do = self.iter(retry_state=retry_state)
  File "/home/runner/.local/lib/python3.8/site-packages/tenacity/__init__.py", line 314, in iter
    return fut.result()
  File "/usr/lib/python3.8/concurrent/futures/_base.py", line 437, in result
    return self.__get_result()
  File "/usr/lib/python3.8/concurrent/futures/_base.py", line 389, in __get_result
    raise self._exception
  File "/home/runner/.local/lib/python3.8/site-packages/tenacity/__init__.py", line 382, in __call__
    result = fn(*args, **kwargs)
  File "src/update.py", line 253, in download_watch_file
    r = session.get(url)
  File "/usr/lib/python3/dist-packages/requests/sessions.py", line 548, in get
    return self.request('GET', url, **kwargs)
  File "/usr/lib/python3/dist-packages/requests/sessions.py", line 535, in request
    resp = self.send(prep, **send_kwargs)
  File "/usr/lib/python3/dist-packages/requests/sessions.py", line 648, in send
    r = adapter.send(request, **kwargs)
  File "/usr/lib/python3/dist-packages/requests/adapters.py", line 498, in send
    raise ConnectionError(err, request=request)
requests.exceptions.ConnectionError: ('Connection aborted.', RemoteDisconnected('Remote end closed connection without response'))
2023-11-18 06:42:38 [INFO] GET https://sources.debian.org/api/src/zsh/5.9-5/debian/watch
2023-11-18 06:42:39 [INFO] GET https://sources.debian.org/data/main/r/rustc/1.70.0%2Bdfsg1-1/debian/watch
2023-11-18 06:42:39 [INFO] GET https://sources.debian.org/data/main/z/zsh/5.9-5/debian/watch
2023-11-18 06:42:39 [INFO] GET https://sources.debian.org/data/main/p/python3-defaults/3.11.4-5/debian/watch
2023-11-18 06:42:40 [INFO] python3-defaults 3.12.0: https://www.python.org/ftp/python/3.12.0/Python-3.12.0.tar.xz
2023-11-18 06:42:40 [INFO] rustc 1.74.0: https://static.rust-lang.org/dist/rustc-1.74.0-src.tar.xz
2023-11-18 06:42:40 [INFO] zsh 5.9: https://www.zsh.org/pub/zsh-5.9.tar.xz
2023-11-18 06:42:40 [INFO] no updates found
2023-11-18 06:42:40 [ERROR] failed: ffmpeg
