2024-02-23 23:15:16 [INFO] persisted: Persisted(last_successful_crawls={'ffmpeg': '2024-02-23 22:15:11.103686+00:00', 'golang-defaults': '2024-02-23 22:15:07.188556+00:00', 'python3-defaults': '2024-02-23 22:15:09.787382+00:00', 'rustc': '2024-02-23 22:15:10.030706+00:00', 'zsh': '2024-02-23 22:15:10.390598+00:00'})
2024-02-23 23:15:16 [INFO] config: Config(feed=FeedConfig(base_url='https://release-feeds.zhimingwang.org/', author='release-feeds', aggregate_title='Aggregate software releases'), packages=['ffmpeg', 'golang-defaults', 'python3-defaults', 'rustc', 'zsh'])
2024-02-23 23:15:16 [INFO] GET https://sources.debian.org/api/src/python3-defaults/
2024-02-23 23:15:16 [INFO] GET https://sources.debian.org/api/src/rustc/
2024-02-23 23:15:16 [INFO] GET https://sources.debian.org/api/src/zsh/
2024-02-23 23:15:16 [INFO] GET https://sources.debian.org/api/src/ffmpeg/
2024-02-23 23:15:17 [INFO] golang-defaults 1.22.0: https://golang.org/dl/go1.22.0.src.tar.gz
2024-02-23 23:15:20 [WARNING] retrying download_watch_file for rustc (attempt #1)
2024-02-23 23:15:20 [WARNING] retrying download_watch_file for zsh (attempt #1)
2024-02-23 23:15:20 [WARNING] retrying download_watch_file for python3-defaults (attempt #1)
2024-02-23 23:15:20 [WARNING] retrying download_watch_file for ffmpeg (attempt #1)
2024-02-23 23:15:22 [INFO] GET https://sources.debian.org/api/src/rustc/
2024-02-23 23:15:22 [INFO] GET https://sources.debian.org/api/src/zsh/
2024-02-23 23:15:22 [INFO] GET https://sources.debian.org/api/src/python3-defaults/
2024-02-23 23:15:22 [INFO] GET https://sources.debian.org/api/src/ffmpeg/
2024-02-23 23:15:25 [WARNING] retrying download_watch_file for zsh (attempt #2)
2024-02-23 23:15:25 [WARNING] retrying download_watch_file for rustc (attempt #2)
2024-02-23 23:15:26 [WARNING] retrying download_watch_file for ffmpeg (attempt #2)
2024-02-23 23:15:27 [WARNING] retrying download_watch_file for python3-defaults (attempt #2)
2024-02-23 23:15:29 [INFO] GET https://sources.debian.org/api/src/zsh/
2024-02-23 23:15:29 [INFO] GET https://sources.debian.org/api/src/rustc/
2024-02-23 23:15:30 [INFO] GET https://sources.debian.org/api/src/ffmpeg/
2024-02-23 23:15:31 [INFO] GET https://sources.debian.org/api/src/python3-defaults/
2024-02-23 23:15:33 [WARNING] retrying download_watch_file for zsh (attempt #3)
2024-02-23 23:15:33 [ERROR] failed to update entry for zsh: no sid version found for zsh: {"package":"zsh","path":"zsh","pathl":[["zsh","/src/zsh/"]],"suite":"","type":"package","versions":[{"area":"main","suites":["trixie"],"version":"5.9-6"},{"area":"main","suites":["bookworm"],"version":"5.9-4"},{"area":"main","suites":["bullseye"],"version":"5.8-6+deb11u1"},{"area":"main","suites":["buster"],"version":"5.7.1-1+deb10u1"},{"area":"main","suites":["stretch"],"version":"5.3.1-4"},{"area":"main","suites":["jessie","jessie-kfreebsd"],"version":"5.0.7-5"},{"area":"main","suites":["wheezy"],"version":"4.3.17-1"},{"area":"main","suites":["squeeze"],"version":"4.3.10-14"},{"area":"main","suites":["lenny"],"version":"4.3.6-6"},{"area":"main","suites":["etch","etch-m68k"],"version":"4.3.2-25"},{"area":"main","suites":["sarge"],"version":"4.2.5-7"},{"area":"main","suites":["woody"],"version":"4.0.4-33"},{"area":"main","suites":["potato"],"version":"3.1.9.dev6-7"},{"area":"main","suites":["slink"],"version":"3.1.2-10"},{"area":"main","suites":["hamm"],"version":"3.1.2-8"}]}

2024-02-23 23:15:34 [ERROR] failed to update entry for rustc
Traceback (most recent call last):
  File "/usr/lib/python3/dist-packages/urllib3/connectionpool.py", line 422, in _make_request
    six.raise_from(e, None)
  File "<string>", line 3, in raise_from
  File "/usr/lib/python3/dist-packages/urllib3/connectionpool.py", line 417, in _make_request
    httplib_response = conn.getresponse()
  File "/usr/lib/python3.8/http/client.py", line 1348, in getresponse
    response.begin()
  File "/usr/lib/python3.8/http/client.py", line 316, in begin
    version, status, reason = self._read_status()
  File "/usr/lib/python3.8/http/client.py", line 277, in _read_status
    line = str(self.fp.readline(_MAXLINE + 1), "iso-8859-1")
  File "/usr/lib/python3.8/socket.py", line 669, in readinto
    return self._sock.recv_into(b)
  File "/usr/lib/python3/dist-packages/urllib3/contrib/pyopenssl.py", line 326, in recv_into
    raise timeout("The read operation timed out")
socket.timeout: The read operation timed out

During handling of the above exception, another exception occurred:

Traceback (most recent call last):
  File "/usr/lib/python3/dist-packages/requests/adapters.py", line 439, in send
    resp = conn.urlopen(
  File "/usr/lib/python3/dist-packages/urllib3/connectionpool.py", line 720, in urlopen
    retries = retries.increment(
  File "/usr/lib/python3/dist-packages/urllib3/util/retry.py", line 400, in increment
    raise six.reraise(type(error), error, _stacktrace)
  File "/usr/lib/python3/dist-packages/six.py", line 703, in reraise
    raise value
  File "/usr/lib/python3/dist-packages/urllib3/connectionpool.py", line 666, in urlopen
    httplib_response = self._make_request(
  File "/usr/lib/python3/dist-packages/urllib3/connectionpool.py", line 424, in _make_request
    self._raise_timeout(err=e, url=url, timeout_value=read_timeout)
  File "/usr/lib/python3/dist-packages/urllib3/connectionpool.py", line 331, in _raise_timeout
    raise ReadTimeoutError(
urllib3.exceptions.ReadTimeoutError: HTTPSConnectionPool(host='sources.debian.org', port=443): Read timed out. (read timeout=5)

During handling of the above exception, another exception occurred:

Traceback (most recent call last):
  File "src/update.py", line 354, in try_updating_registry_entry
    entry = try_updating_entry(package, existing_entry=existing_entry)
  File "src/update.py", line 319, in try_updating_entry
    latest_version = get_package_version(package)
  File "src/update.py", line 310, in get_package_version
    acquire_watch_file(package, debian_dir)
  File "src/update.py", line 276, in acquire_watch_file
    download_watch_file(package, destdir)
  File "/home/runner/.local/lib/python3.8/site-packages/tenacity/__init__.py", line 289, in wrapped_f
    return self(f, *args, **kw)
  File "/home/runner/.local/lib/python3.8/site-packages/tenacity/__init__.py", line 379, in __call__
    do = self.iter(retry_state=retry_state)
  File "/home/runner/.local/lib/python3.8/site-packages/tenacity/__init__.py", line 314, in iter
    return fut.result()
  File "/usr/lib/python3.8/concurrent/futures/_base.py", line 437, in result
    return self.__get_result()
  File "/usr/lib/python3.8/concurrent/futures/_base.py", line 389, in __get_result
    raise self._exception
  File "/home/runner/.local/lib/python3.8/site-packages/tenacity/__init__.py", line 382, in __call__
    result = fn(*args, **kwargs)
  File "src/update.py", line 238, in download_watch_file
    r = session.get(url)
  File "/usr/lib/python3/dist-packages/requests/sessions.py", line 548, in get
    return self.request('GET', url, **kwargs)
  File "/usr/lib/python3/dist-packages/requests/sessions.py", line 535, in request
    resp = self.send(prep, **send_kwargs)
  File "/usr/lib/python3/dist-packages/requests/sessions.py", line 648, in send
    r = adapter.send(request, **kwargs)
  File "/usr/lib/python3/dist-packages/requests/adapters.py", line 529, in send
    raise ReadTimeout(e, request=request)
requests.exceptions.ReadTimeout: HTTPSConnectionPool(host='sources.debian.org', port=443): Read timed out. (read timeout=5)
2024-02-23 23:15:35 [WARNING] retrying download_watch_file for ffmpeg (attempt #3)
2024-02-23 23:15:35 [ERROR] failed to update entry for ffmpeg: no sid version found for ffmpeg: {"package":"ffmpeg","path":"ffmpeg","pathl":[["ffmpeg","/src/ffmpeg/"]],"suite":"","type":"package","versions":[{"area":"main","suites":["trixie"],"version":"7:6.1.1-1"},{"area":"main","suites":["bookworm"],"version":"7:5.1.4-0+deb12u1"},{"area":"main","suites":["bullseye"],"version":"7:4.3.6-0+deb11u1"},{"area":"main","suites":["buster"],"version":"7:4.1.9-0+deb10u1"},{"area":"main","suites":["stretch"],"version":"7:3.2.14-1~deb9u1"},{"area":"main","suites":["jessie-backports"],"version":"7:3.2.10-1~deb9u1~bpo8+1"},{"area":"main","suites":["jessie-backports"],"version":"7:3.2.5-1~bpo8+1"},{"area":"main","suites":["squeeze-lts"],"version":"4:0.5.10-1+deb6u1"},{"area":"main","suites":["squeeze"],"version":"4:0.5.10-1"},{"area":"main","suites":["etch"],"version":"0.cvs20060823-8+etch1"},{"area":"main","suites":["etch-m68k"],"version":"0.cvs20060823-8"},{"area":"main","suites":["sarge"],"version":"0.cvs20050313-2sarge1"}]}

2024-02-23 23:15:37 [ERROR] failed to update entry for python3-defaults
Traceback (most recent call last):
  File "/usr/lib/python3/dist-packages/urllib3/connectionpool.py", line 422, in _make_request
    six.raise_from(e, None)
  File "<string>", line 3, in raise_from
  File "/usr/lib/python3/dist-packages/urllib3/connectionpool.py", line 417, in _make_request
    httplib_response = conn.getresponse()
  File "/usr/lib/python3.8/http/client.py", line 1348, in getresponse
    response.begin()
  File "/usr/lib/python3.8/http/client.py", line 316, in begin
    version, status, reason = self._read_status()
  File "/usr/lib/python3.8/http/client.py", line 277, in _read_status
    line = str(self.fp.readline(_MAXLINE + 1), "iso-8859-1")
  File "/usr/lib/python3.8/socket.py", line 669, in readinto
    return self._sock.recv_into(b)
  File "/usr/lib/python3/dist-packages/urllib3/contrib/pyopenssl.py", line 328, in recv_into
    return self.recv_into(*args, **kwargs)
  File "/usr/lib/python3/dist-packages/urllib3/contrib/pyopenssl.py", line 326, in recv_into
    raise timeout("The read operation timed out")
socket.timeout: The read operation timed out

During handling of the above exception, another exception occurred:

Traceback (most recent call last):
  File "/usr/lib/python3/dist-packages/requests/adapters.py", line 439, in send
    resp = conn.urlopen(
  File "/usr/lib/python3/dist-packages/urllib3/connectionpool.py", line 720, in urlopen
    retries = retries.increment(
  File "/usr/lib/python3/dist-packages/urllib3/util/retry.py", line 400, in increment
    raise six.reraise(type(error), error, _stacktrace)
  File "/usr/lib/python3/dist-packages/six.py", line 703, in reraise
    raise value
  File "/usr/lib/python3/dist-packages/urllib3/connectionpool.py", line 666, in urlopen
    httplib_response = self._make_request(
  File "/usr/lib/python3/dist-packages/urllib3/connectionpool.py", line 424, in _make_request
    self._raise_timeout(err=e, url=url, timeout_value=read_timeout)
  File "/usr/lib/python3/dist-packages/urllib3/connectionpool.py", line 331, in _raise_timeout
    raise ReadTimeoutError(
urllib3.exceptions.ReadTimeoutError: HTTPSConnectionPool(host='sources.debian.org', port=443): Read timed out. (read timeout=5)

During handling of the above exception, another exception occurred:

Traceback (most recent call last):
  File "src/update.py", line 354, in try_updating_registry_entry
    entry = try_updating_entry(package, existing_entry=existing_entry)
  File "src/update.py", line 319, in try_updating_entry
    latest_version = get_package_version(package)
  File "src/update.py", line 310, in get_package_version
    acquire_watch_file(package, debian_dir)
  File "src/update.py", line 276, in acquire_watch_file
    download_watch_file(package, destdir)
  File "/home/runner/.local/lib/python3.8/site-packages/tenacity/__init__.py", line 289, in wrapped_f
    return self(f, *args, **kw)
  File "/home/runner/.local/lib/python3.8/site-packages/tenacity/__init__.py", line 379, in __call__
    do = self.iter(retry_state=retry_state)
  File "/home/runner/.local/lib/python3.8/site-packages/tenacity/__init__.py", line 314, in iter
    return fut.result()
  File "/usr/lib/python3.8/concurrent/futures/_base.py", line 437, in result
    return self.__get_result()
  File "/usr/lib/python3.8/concurrent/futures/_base.py", line 389, in __get_result
    raise self._exception
  File "/home/runner/.local/lib/python3.8/site-packages/tenacity/__init__.py", line 382, in __call__
    result = fn(*args, **kwargs)
  File "src/update.py", line 238, in download_watch_file
    r = session.get(url)
  File "/usr/lib/python3/dist-packages/requests/sessions.py", line 548, in get
    return self.request('GET', url, **kwargs)
  File "/usr/lib/python3/dist-packages/requests/sessions.py", line 535, in request
    resp = self.send(prep, **send_kwargs)
  File "/usr/lib/python3/dist-packages/requests/sessions.py", line 648, in send
    r = adapter.send(request, **kwargs)
  File "/usr/lib/python3/dist-packages/requests/adapters.py", line 529, in send
    raise ReadTimeout(e, request=request)
requests.exceptions.ReadTimeout: HTTPSConnectionPool(host='sources.debian.org', port=443): Read timed out. (read timeout=5)
2024-02-23 23:15:37 [INFO] no updates found
2024-02-23 23:15:37 [ERROR] failed: zsh, rustc, ffmpeg, python3-defaults
